Workbook

Sheet Guide
A1: DATA ANALYST PRACTICE LAB | B1: Excel 2013 • Data Cleaning • Joining • Analysis • KPI • Dashboard
A2: เป้าหมาย | B2: ฝึกตั้งแต่ Raw Data → Data Cleansing → รวมข้อมูลหลายตาราง → KPI → วิเคราะห์ → Visualization
A3: ระดับ | B3: Intermediate / Upper-Intermediate
A4: โจทย์หลัก | B4: บริษัทจำลองที่มีข้อมูล Sales, Customers, Employees, Products, Performance และ Costs
A5: จำนวนข้อมูล | B5: Sales 180 รายการ • Employees 95 คน • Customers 50 ราย • Products 20 รายการ • Performance 95 ราย • Costs 42 รายการ
A6: ข้อควรระวัง | B6: Raw Data ตั้งใจใส่ช่องว่าง ค่าว่าง รูปแบบข้อความไม่สม่ำเสมอ และข้อมูลที่ต้องตรวจสอบ
A7: แนะนำ | B7: ทำโจทย์ใน Sheet 03 ก่อนเปิดดู Sheet 04-06
A8: Excel 2013 | B8: เน้น Table, SUMIFS, COUNTIFS, IF, VLOOKUP, INDEX/MATCH, PivotTable, Charts และ Data Validation
A9: ไฟล์นี้ | B9: ไม่มีสูตรเฉลยใน Raw Data เพื่อให้ฝึกจริง ส่วนเฉลยเป็นตัวอย่างแนวคิดและสูตร

Sheet 02_Raw_Sales
A1: Sale_ID | B1: Sale_Date | C1: Employee_ID | D1: Customer_ID | E1: Product_ID | F1: Quantity | G1: Discount | H1: Sales_Amount | I1: Cost_Amount | J1: Profit | K1: Region_Raw | L1: Order_Status
A2: S0001 | B2: 45792 | C2: E069 | D2: C018 | E2: P018 | F2: 5 | G2: 0.12 | H2: 15840 | I2: 12000 | J2: 3840 | K2: Northeast | L2: Completed
A3: S0002 | B3: 45774 | C3: E042 | D3: C027 | E3: P018 | F3: 8 | G3: 0 | H3: 28800 | I3: 19200 | J3: 9600 | K3: South | L3: Completed
A4: S0003 | B4: 45820 | C4: E041 | D4: C040 | E4: P011 | F4: 17 | G4: 0.05 | H4: 30685 | I4: 20400 | J4: 10285 | K4: Central | L4: Pending
A5: S0004 | B5: 45779 | C5: E079 | D5: C024 | E5: P015 | F5: 6 | G5: 0.12 | H5: 25344 | I5: 19200 | J5: 6144 | K5: South | L5: Completed
A6: S0005 | B6: 45665 | C6: E004 | D6: C029 | E6: P016 | F6: 3 | G6: 0.03 | H6: 12222 | I6: 8400 | J6: 3822 | K6: South | L6: Completed
A7: S0006 | B7: 45710 | C7: E082 | D7: C017 | E7: P020 | F7: 8 | G7: 0.1 | H7: 37440 | I7: 28000 | J7: 9440 | K7: East | L7: Completed
A8: S0007 | B8: 45702 | C8: E016 | D8: C032 | E8: P007 | F8: 5 | G8: 0.1 | H8: 47250 | I8: 37500 | J8: 9750 | K8: East | L8: Completed
A9: S0008 | B9: 45754 | C9: E010 | D9: C021 | E9: P009 | F9: 9 | G9: 0.05 | H9: 58140 | I9: 40500 | J9: 17640 | K9: East | L9: Completed
A10: S0009 | B10: 45684 | C10: E047 | D10: C011 | E10: P006 | F10: 13 | G10: 0.08 | H10: 86112 | I10: 62400 | J10: 23712 | K10: South | L10: Completed
A11: S0010 | B11: 45833 | C11: E028 | D11: C031 | E11: P016 | F11: 10 | G11: 0.03 | H11: 40740 | I11: 28000 | J11: 12740 | K11: East | L11: Completed
A12: S0011 | B12: 45824 | C12: E009 | D12: C010 | E12: P008 | F12: 9 | G12: 0.1 | H12: 72900 | I12: 58500 | J12: 14400 | K12: East | L12: Completed
A13: S0012 | B13: 45739 | C13: E001 | D13: C011 | E13: P013 | F13: 13 | G13: 0.1 | H13: 105300 | I13: 84500 | J13: 20800 | K13: South | L13: Completed
... A18: S0017 | B18: 45742 | C18: E094 | D18: C028 | E18: P002 | F18: 10 | G18: 0.05 | H18: 361000 | I18: 300000 | J18: 61000 | K18: South | L18: Completed
A19: S0018 | B19: 45707 | C19: E012 | D19: C023 | E19: P008 | G19: 0.05 | H19: 25650 | I19: 19500 | J19: 6150 | K19: North | L19: Completed
A20: S0019 | B20: 45709 | C20: E073 | D20: C017 | E20: P001 | F20: 5 | G20: 0 | H20: 260000 | I20: 210000 | J20: 50000 | K20: East | L20: Pending
A21: S0020 | B21: 45678 | C21: E037 | D21: C015 | E21: P010 | F21: 6 | G21: 0.12 | H21: 17952 | I21: 13200 | J21: 4752 | K21: Northeast | L21: สุกี้
A22: S0021 | B22: 45701 | C22: E081 | D22: C042 | E22: P015 | F22: 9 | G22: 0 | H22: 43200 | I22: 28800 | J22: 14400 | K22: Central | L22: Completed
A23: S0022 | B23: 45767 | C23: E021 | D23: C003 | E23: P002 | F23: 14 | G23: 0.1 | H23: 478800 | I23: 420000 | J23: 58800 | K23: North | L23: Completed
A24: S0023 | B24: 45740 | C24: E044 | D24: C043 | E24: P003 | F24: 12 | G24: 0 | H24: 144000 | I24: 102000 | J24: 42000 | K24: Central | L24: Completed
A25: S0024 | B25: 45835 | C25: E066 | D25: C019 | E25: P019 | F25: 8 | G25: 0 | H25: 28800 | I25: 19200 | J25: 9600 | K25: Central | L25: Cancelled
A26: S0025 | B26: 45669 | C26: E074 | D26: C050 | E26: P015 | F26: 6 | G26: 0 | H26: 28800 | I26: 19200 | J26: 9600 | K26: South | L26: Cancelled
A27: S0026 | B27: 45692 | C27: E048 | D27: C026 | E27: P016 | F27: 14 | G27: 0.1 | H27: 52920 | I27: 39200 | J27: 13720 | K27: Northeast | L27: Completed
A28: S0027 | B28: 45716 | C28: E045 | D28: C042 | E28: P008 | F28: 13 | G28: 0 | H28: 117000 | I28: 84500 | J28: 32500 | K28: Central | L28: Completed
A29: S0028 | B29: 45751 | C29: E076 | D29: C012 | E29: P006 | F29: 6 | G29: 0 | H29: 43200 | I29: 28800 | J29: 14400 | K29: South | L29: Completed
A30: S0029 | B30: 45670 | C30: E059 | D30: C018 | E30: P001 | F30: 2 | G30: 0.08 | H30: 95680 | I30: 84000 | J30: 11680 | K30: Northeast | L30: Completed
A31: S0030 | B31: 45798 | C31: E055 | D31: C043 | E31: P015 | F31: 13 | G31: 0 | H31: 62400 | I31: 41600 | J31: 20800 | K31: Central | L31: Completed
... A62: S0061 | B62: 45692 | C62: E056 | D62: C023 | E62: P018 | F62: 15 | G62: 0.12 | H62: 47520 | I62: 36000 | J62: 11520 | K62: North | L62: Cancelled
A63: S0062 | B63: 45738 | C63: E045 | D63: C006 | E63: P014 | F63: 18 | H63: 253440 | I63: 207000 | J63: 46440 | K63: North | L63: Completed
A64: S0063 | B64: 45746 | C64: E087 | D64: C040 | E64: P015 | F64: 10 | G64: 0.1 | H64: 43200 | I64: 32000 | J64: 11200 | K64: Central | L64: Completed
A65: S0064 | B65: 45687 | C65: E008 | D65: C016 | E65: P004 | F65: 11 | G65: 0.1 | H65: 27720 | I65: 19800 | J65: 7920 | K65: East | L65: Pending
A66: S0065 | B66: 45766 | C66: E015 | D66: C029 | E66: P014 | F66: 18 | G66: 0.03 | H66: 279360 | I66: 207000 | J66: 72360 | K66: South | L66: Completed
A67: S0066 | B67: 45726 | C67: E035 | D67: C006 | E67: P013 | F67: 2 | G67: 0 | H67: 18000 | I67: 13000 | J67: 5000 | K67: North | L67: Completed
A68: S0067 | B68: 45733 | C68: E002 | D68: C037 | E68: P008 | F68: 2 | G68: 0.1 | H68: 16200 | I68: 13000 | J68: 3200 | K68: North | L68: Pending
A69: S0068 | B69: 45715 | C69: E048 | D69: C004 | E69: P017 | F69: 18 | G69: 0.12 | H69: 102960 | I69: 75600 | J69: 27360 | K69: Central | L69: Completed
A70: S0069 | B70: 45757 | C70: E021 | D70: C030 | E70: P020 | F70: 2 | G70: 0.05 | H70: 9880 | I70: 7000 | J70: 2880 | K70: Central | L70: Cancelled
A71: S0070 | B71: 45816 | C71: E061 | D71: C038 | E71: P001 | F71: 9 | G71: 0 | H71: 468000 | I71: 378000 | J71: 90000 | K71: Central | L71: Completed
A72: S0071 | B72: 45808 | C72: E054 | D72: C044 | E72: P018 | F72: 12 | G72: 0.12 | H72: 38016 | I72: 28800 | J72: 9216 | K72: East | L72: Completed
A73: S0072 | B73: 45677 | C73: E092 | D73: C039 | E73: P015 | F73: 6 | G73: 0.1 | H73: 25920 | I73: 19200 | J73: 6720 | K73: Central | L73: Pending
A74: S0073 | B74: 45725 | C74: E067 | D74: C015 | E74: P004 | F74: 9 | G74: 0.08 | H74: 23184 | I74: 16200 | J74: 6984 | K74: Northeast | L74: Completed
...

Sheet 02_Products
A1: Product_ID | B1: Product_Name | C1: Category | D1: Unit_Cost | E1: List_Price
A2: P001 | B2: Laptop Pro 14 | C2: IT Equipment | D2: 42000 | E2: 52000
A3: P002 | B3: Laptop Business 15 | C3: IT Equipment | D3: 30000 | E3: 38000
A4: P003 | B4: Monitor 27 Inch | C4: IT Equipment | D4: 8500 | E4: 12000
A5: P004 | B5: Mechanical Keyboard | C5: Accessories | D5: 1800 | E5: 2800
A6: P005 | B6: Wireless Mouse | C6: Accessories | D6: 650 | E6: 1100
A7: P006 | B7: Office Chair Ergo | C7: Office | D7: 4800 | E7: 7200
A8: P007 | B8: Standing Desk | C8: Office | D8: 7500 | E8: 10500
A9: P008 | B9: Printer Laser | C9: Office | D9: 6500 | E9: 9000
A10: P009 | B10: Network Switch | C10: IT Equipment | D10: 4500 | E10: 6800
A11: P010 | B11: SSD 1TB | C11: IT Equipment | D11: 2200 | E11: 3400
A12: P011 | B12: Webcam HD | C12: Accessories | D12: 1200 | E12: 1900
A13: P012 | B13: Headset Pro | C13: Accessories | D13: 1600 | E13: 2500
... A21: P020 | B21: Barcode Scanner | C21: Operations | D21: 3500 | E21: 5200

Sheet 02_Employees
A1: Employee_ID | B1: Employee_Name | C1: Department | D1: Level | E1: Monthly_Salary | F1: Performance_Target
A2: E001 | B2: นที นาคะ | C2: Sales | D2: Mid | E2: 51000 | F2: 800000
A3: E002 | B3: วรพล ธนากุล | C3: Sales | D3: Senior | E3: 39000 | F3: 1130000
A4: E003 | B4: อัญชลี ทองดี | C4: Sales | D4: Junior | E4: 32000 | F4: 1040000
A5: E004 | B5: อัญชลี เจริญกิจ | C5: Sales | D5: Mid | E5: 44500 | F5: 720000
A6: E005 | B6: ปวีณา วัฒนชัย | C6: Sales | D6: Mid | E6: 31500 | F6: 1060000
A7: E006 | B7: สุภัสสรา ศักดิ์ชัย | C7: Sales | D7: Mid | E7: 37500 | F7: 720000
A8: E007 | B8: ณัฐริกา ภักดี | C8: Sales | D8: Senior | E8: 34000 | F8: 1200000
A9: E008 | B9: วรัญญา บุญมี | C9: Sales | D9: Junior | E9: 51000 | F9: 1130000
A10: E009 | B10: สิริกานต์ มงคลชัย | C10: Sales | D10: Mid | E10: 46000 | F10: 820000
A11: E010 | B11: สุภัสสรา ศรีทอง | C11: Sales | D11: Senior | E11: 30500 | F11: 1100000
A12: E011 | B12: ณิชา ภักดี | C12: Sales | D12: Senior | E12: 28500 | F12: 1120000
A13: E012 | B13: วรเมธ กาญจนวัฒน์ | C13: Sales | D13: Mid | E13: 31000 | F13: 1110000
... A96: E095 | B96: ณัฐณิชา ไพศาล | C96: Customer Service | D96: Mid | E96: 33000 | F96: 530000

Sheet 02_Raw_Performance
A1: Employee_ID | B1: Employee_Name | C1: Department | D1: Monthly_Salary | E1: Performance_Target | F1: Actual_Result | G1: Quality_Score | H1: Attendance_Score | I1: Teamwork_Score | J1: Customer_Score | K1: Overall_Score
A2: E001 | B2: นที นาคะ | C2: Sales | D2: 51000 | E2: 800000 | F2: 865500 | G2: 90.7 | H2: 95.3 | I2: 91.1 | J2: 81.6 | K2: 97.7
A3: E002 | B3: วรพล ธนากุล | C3: Sales | D3: 39000 | E3: 1130000 | F3: 904600 | G3: 81.4 | H3: 94.8 | I3: 68 | J3: 73.3 | K3: 79.6
A4: E003 | B4: อัญชลี ทองดี | C4: Sales | D4: 32000 | E4: 1040000 | F4: 1103000 | G4: 78.3 | H4: 93.3 | I4: 76.4 | J4: 96.2 | K4: 94.8
A5: E004 | B5: อัญชลี เจริญกิจ | C5: Sales | D5: 44500 | E5: 720000 | F5: 869100 | G5: 70.9 | H5: 91.9 | I5: 88.5 | J5: 88.8 | K5: 99.9
A6: E005 | B6: ปวีณา วัฒนชัย | C6: Sales | D6: 31500 | E6: 1060000 | F6: 1030900 | G6: 71.8 | H6: 91.3 | I6: 74.8 | J6: 86.2 | K6: 87.7
A7: E006 | B7: สุภัสสรา ศักดิ์ชัย | C7: Sales | D7: 37500 | E7: 720000 | F7: 926400 | G7: 75.8 | H7: 89.9 | I7: 78.9 | J7: 92.3 | K7: 100
A8: E007 | B8: ณัฐริกา ภักดี | C8: Sales | D8: 34000 | E8: 1200000 | F8: 863500 | G8: 95.1 | H8: 93.3 | I8: 72.7 | J8: 71.2 | K8: 78.7
A9: E008 | B9: วรัญญา บุญมี | C9: Sales | D9: 51000 | E9: 1130000 | F9: 1251100 | G9: 80.5 | H9: 94.7 | I9: 71 | J9: 81.4 | K9: 94.7
A10: E009 | B10: สิริกานต์ มงคลชัย | C10: Sales | D10: 46000 | E10: 820000 | F10: 731800 | G10: 81.1 | H10: 91.3 | I10: 64.7 | J10: 99 | K10: 86.8
A11: E010 | B11: สุภัสสรา ศรีทอง | C11: Sales | D11: 30500 | E11: 1100000 | F11: 808000 | G11: 83.6 | H11: 86.9 | I11: 60 | J11: 84.8 | K11: 77.2
A12: E011 | B12: ณิชา ภักดี | C12: Sales | D12: 28500 | E12: 1120000 | F12: 1132800 | G12: 93.4 | H12: 95.6 | I12: 78.5 | J12: 76.4 | K12: 93.1
A13: E012 | B13: วรเมธ กาญจนวัฒน์ | C13: Sales | D13: 31000 | E13: 1110000 | F13: 1387300 | G13: 90.4 | H13: 89 | I13: 80.4 | J13: 85.2 | K13: 100
... A96: E095 | B96: ณัฐณิชา ไพศาล | C96: Customer Service | D96: 33000 | E96: 530000 | F96: 558600 | G96: 82.1 | H96: 92.8 | I96: 70.9 | J96: 96.6 | K96: 94.7

Sheet 02_Overhead_Costs
A1: Month | B1: Department | C1: Overhead_Cost | D1: Cost_Type
A2: 2025-01 | B2: Sales | C2: 167933.1 | D2: Office
A3: 2025-01 | B3: Finance | C3: 91811.47 | D3: Software
A4: 2025-01 | B4: IT | C4: 201803.8 | D4: Office
A5: 2025-01 | B5: HR | C5: 75217.68 | D5: Training
A6: 2025-01 | B6: Operations | C6: 165857.4 | D6: Office
A7: 2025-01 | B7: Marketing | C7: 115749.33 | D7: Software
A8: 2025-01 | B8: Customer Service | C8: 99947.07 | D8: Travel
A9: 2025-02 | B9: Sales | C9: 197146.49 | D9: Office
A10: 2025-02 | B10: Finance | C10: 102682.81 | D10: Utilities
A11: 2025-02 | B11: IT | C11: 207815.77 | D11: Travel
A12: 2025-02 | B12: HR | C12: 75250.09 | D12: Training
A13: 2025-02 | B13: Operations | C13: 188305.06 | D13: Training
... A43: 2025-06 | B43: Customer Service | C43: 108356.21 | D43: Training

Sheet Sales
A1: Sale_ID | B1: Sale_Date | C1: Month | D1: Month* | E1: Employee_ID | F1: Customer_ID | G1: Product_ID | H1: Quantity | I1: Discount | J1: Sales_Amount | K1: Cost_Amount | L1: Profit | M1: Region | N1: Order_Status | O1: Employee_Name | P1: Department | Q1: Customer_Name | R1: Customer_Segment | S1: Customer_Tier | T1: Product_Name | U1: Category | V1: Unit_Cost | W1: List_Price | X1: Net_Sales | Y1: Margin_%
A2: S0001 | B2: 45792 | C2: =MONTH(Sales[[#This Row],[Sale_Date]]) -> 5 | D2: =CHOOSE(C2,"January","February","March","April","May","June","July","August","September","October","November","December") -> May | E2: E069 | F2: C018 | G2: P018 | H2: 5 | I2: 0.12 | J2: 15840 | K2: 12000 | L2: 3840 | M2: Northeast | N2: Completed | O2: =INDEX(Employees[#All],MATCH(Sales[[#This Row],[Employee_ID]],Employees[[#All],[Employee_ID]],0),MATCH(Sales[[#Headers],[Employee_Name]],Employees[#Headers],0)) -> อัครพล จันทร์โอชา | P2: =INDEX(Employees[#All],MATCH(Sales[[#This Row],[Employee_ID]],Employees[[#All],[Employee_ID]],0),MATCH(Sales[[#Headers],[Department]],Employees[#Headers],0)) -> Operations | Q2: =VLOOKUP(Sales[[#This Row],[Customer_ID]],Customer[#All],MATCH(Sales[[#Headers],[Customer_Name]],Customer[#Headers],0),FALSE) -> บริษัท ซันไรส์ จำกัด | R2: =VLOOKUP(Sales[[#This Row],[Customer_ID]],Customer[#All],MATCH(Sales[[#Headers],[Customer_Segment]],Customer[#Headers],0),FALSE) -> Retail Chain | S2: =VLOOKUP(Sales[[#This Row],[Customer_ID]],Customer[#All],MATCH(Sales[[#Headers],[Customer_Tier]],Customer[#Headers],0),FALSE) -> Bronze | T2: =INDEX(Product[#All],MATCH(Sales[[#This Row],[Product_ID]],Product[[#All],[Product_ID]],0),MATCH(Sales[[#Headers],[Product_Name]],Product[#Headers],0)) -> USB-C Dock | U2: =INDEX(Product[#All],MATCH(Sales[[#This Row],[Product_ID]],Product[[#All],[Product_ID]],0),MATCH(Sales[[#Headers],[Category]],Product[#Headers],0)) -> Accessories | V2: =INDEX(Product[#All],MATCH(Sales[[#This Row],[Product_ID]],Product[[#All],[Product_ID]],0),MATCH(Sales[[#Headers],[Unit_Cost]],Product[#Headers],0)) -> 2400 | W2: =INDEX(Product[#All],MATCH(Sales[[#This Row],[Product_ID]],Product[[#All],[Product_ID]],0),MATCH("List_Price",Product[#Headers],0)) -> 3600 | X2: =Sales[[#This Row],[Quantity]]*(Sales[[#This Row],[List_Price]]*(1-Sales[[#This Row],[Discount]])) -> 15840 | Y2: =Sales[[#This Row],[Profit]]/Sales[[#This Row],[Cost_Amount]] -> 0.32
A3: S0002 | B3: 45774 | C3: =MONTH(Sales[[#This Row],[Sale_Date]]) -> 4 | D3: =CHOOSE(C3,"January","February","March","April","May","June","July","August","September","October","November","December") -> April | E3: E042 | F3: C027 | G3: P018 | H3: 8 | I3: 0 | J3: 28800 | K3: 19200 | L3: 9600 | M3: South | N3: Completed | O3: ศุภชัย วิชัยดิษฐ์ | P3: IT | Q3: บริษัท อินโนเวท จำกัด | R3: Retail Chain | S3: Gold | T3: USB-C Dock | U3: =INDEX(Product[#All],MATCH(Sales[[#This Row],[Product_ID]],Product[[#All],[Product_ID]],0),MATCH(Sales[[#Headers],[Category]],Product[#Headers],0)) -> Accessories | V3: =INDEX(Product[#All],MATCH(Sales[[#This Row],[Product_ID]],Product[[#All],[Product_ID]],0),MATCH(Sales[[#Headers],[Unit_Cost]],Product[#Headers],0)) -> 2400 | W3: =INDEX(Product[#All],MATCH(Sales[[#This Row],[Product_ID]],Product[[#All],[Product_ID]],0),MATCH("List_Price",Product[#Headers],0)) -> 3600 | X3: =Sales[[#This Row],[Quantity]]*(Sales[[#This Row],[List_Price]]*(1-Sales[[#This Row],[Discount]])) -> 28800 | Y3: =Sales[[#This Row],[Profit]]/Sales[[#This Row],[Cost_Amount]] -> 0.5
A4: S0003 | B4: 45820 | C4: =MONTH(Sales[[#This Row],[Sale_Date]]) -> 6 | D4: =CHOOSE(C4,"January","February","March","April","May","June","July","August","September","October","November","December") -> June | E4: E041 | F4: C040 | G4: P011 | H4: 17 | I4: 0.05 | J4: 30685 | K4: 20400 | L4: 10285 | M4: Central | N4: Pending | O4: รัชชานนท์ วงศ์วัฒนะ | P4: IT | Q4: บริษัท ซิกม่า จำกัด | R4: Enterprise | S4: Silver | T4: Webcam HD | U4: =INDEX(Product[#All],MATCH(Sales[[#This Row],[Product_ID]],Product[[#All],[Product_ID]],0),MATCH(Sales[[#Headers],[Category]],Product[#Headers],0)) -> Accessories | V4: =INDEX(Product[#All],MATCH(Sales[[#This Row],[Product_ID]],Product[[#All],[Product_ID]],0),MATCH(Sales[[#Headers],[Unit_Cost]],Product[#Headers],0)) -> 1200 | W4: =INDEX(Product[#All],MATCH(Sales[[#This Row],[Product_ID]],Product[[#All],[Product_ID]],0),MATCH("List_Price",Product[#Headers],0)) -> 1900 | X4: =Sales[[#This Row],[Quantity]]*(Sales[[#This Row],[List_Price]]*(1-Sales[[#This Row],[Discount]])) -> 30685 | Y4: =Sales[[#This Row],[Profit]]/Sales[[#This Row],[Cost_Amount]] -> 0.50416667
A5: S0004 | B5: 45779 | C5: =MONTH(Sales[[#This Row],[Sale_Date]]) -> 5 | D5: =CHOOSE(C5,"January","February","March","April","May","June","July","August","September","October","November","December") -> May | E5: E079 | F5: C024 | G5: P015 | H5: 6 | I5: 0.12 | J5: 25344 | K5: 19200 | L5: 6144 | M5: South | N5: Completed | O5: ธนโชติ สกุลไทย | P5: Marketing | Q5: บริษัท ควอลิตี้พาร์ท จำกัด | R5: Retail Chain | S5: Bronze | T5: Router WiFi 6 | U5: =INDEX(Product[#All],MATCH(Sales[[#This Row],[Product_ID]],Product[[#All],[Product_ID]],0),MATCH(Sales[[#Headers],[Category]],Product[#Headers],0)) -> IT Equipment | V5: =INDEX(Product[#All],MATCH(Sales[[#This Row],[Product_ID]],Product[[#All],[Product_ID]],0),MATCH(Sales[[#Headers],[Unit_Cost]],Product[#Headers],0)) -> 3200 | W5: =INDEX(Product[#All],MATCH(Sales[[#This Row],[Product_ID]],Product[[#All],[Product_ID]],0),MATCH("List_Price",Product[#Headers],0)) -> 4800 | X5: =Sales[[#This Row],[Quantity]]*(Sales[[#This Row],[List_Price]]*(1-Sales[[#This Row],[Discount]])) -> 25344 | Y5: =Sales[[#This Row],[Profit]]/Sales[[#This Row],[Cost_Amount]] -> 0.32
A6: S0005 | B6: 45665 | C6: =MONTH(Sales[[#This Row],[Sale_Date]]) -> 1 | D6: =CHOOSE(C6,"January","February","March","April","May","June","July","August","September","October","November","December") -> January | E6: E004 | F6: C029 | G6: P016 | H6: 3 | I6: 0.03 | J6: 12222 | K6: 8400 | L6: 3822 | M6: South | N6: Completed | O6: อัญชลี เจริญกิจ | P6: Sales | Q6: บริษัท ทรีสตาร์ จำกัด | R6: Enterprise | S6: Silver | T6: UPS 1000VA | U6: =INDEX(Product[#All],MATCH(Sales[[#This Row],[Product_ID]],Product[[#All],[Product_ID]],0),MATCH(Sales[[#Headers],[Category]],Product[#Headers],0)) -> IT Equipment | V6: =INDEX(Product[#All],MATCH(Sales[[#This Row],[Product_ID]],Product[[#All],[Product_ID]],0),MATCH(Sales[[#Headers],[Unit_Cost]],Product[#Headers],0)) -> 2800 | W6: =INDEX(Product[#All],MATCH(Sales[[#This Row],[Product_ID]],Product[[#All],[Product_ID]],0),MATCH("List_Price",Product[#Headers],0)) -> 4200 | X6: =Sales[[#This Row],[Quantity]]*(Sales[[#This Row],[List_Price]]*(1-Sales[[#This Row],[Discount]])) -> 12222 | Y6: =Sales[[#This Row],[Profit]]/Sales[[#This Row],[Cost_Amount]] -> 0.455
A7: S0006 | B7: 45710 | C7: =MONTH(Sales[[#This Row],[Sale_Date]]) -> 2 | D7: =CHOOSE(C7,"January","February","March","April","May","June","July","August","September","October","November","December") -> February | E7: E082 | F7: C017 | G7: P020 | H7: 8 | I7: 0.1 | J7: 37440 | K7: 28000 | L7: 9440 | M7: East | N7: Completed | O7: ณัฐณิชา พูนทรัพย์ | P7: Marketing | Q7: บริษัท เรดโรส จำกัด | R7: Retail Chain | S7: Gold | T7: Barcode Scanner | U7: =INDEX(Product[#All],MATCH(Sales[[#This Row],[Product_ID]],Product[[#All],[Product_ID]],0),MATCH(Sales[[#Headers],[Category]],Product[#Headers],0)) -> Operations | V7: =INDEX(Product[#All],MATCH(Sales[[#This Row],[Product_ID]],Product[[#All],[Product_ID]],0),MATCH(Sales[[#Headers],[Unit_Cost]],Product[#Headers],0)) -> 3500 | W7: =INDEX(Product[#All],MATCH(Sales[[#This Row],[Product_ID]],Product[[#All],[Product_ID]],0),MATCH("List_Price",Product[#Headers],0)) -> 5200 | X7: =Sales[[#This Row],[Quantity]]*(Sales[[#This Row],[List_Price]]*(1-Sales[[#This Row],[Discount]])) -> 37440 | Y7: =Sales[[#This Row],[Profit]]/Sales[[#This Row],[Cost_Amount]] -> 0.33714286
A8: S0007 | B8: 45702 | C8: =MONTH(Sales[[#This Row],[Sale_Date]]) -> 2 | D8: =CHOOSE(C8,"January","February","March","April","May","June","July","August","September","October","November","December") -> February | E8: E016 | F8: C032 | G8: P007 | H8: 5 | I8: 0.1 | J8: 47250 | K8: 37500 | L8: 9750 | M8: East | N8: Completed | O8: วุฒิชัย ปรีชานนท์ | P8: Sales | Q8: บริษัท ซิตี้ลิงก์ จำกัด | R8: Retail Chain | S8: Gold | T8: Standing Desk | U8: =INDEX(Product[#All],MATCH(Sales[[#This Row],[Product_ID]],Product[[#All],[Product_ID]],0),MATCH(Sales[[#Headers],[Category]],Product[#Headers],0)) -> Office | V8: =INDEX(Product[#All],MATCH(Sales[[#This Row],[Product_ID]],Product[[#All],[Product_ID]],0),MATCH(Sales[[#Headers],[Unit_Cost]],Product[#Headers],0)) -> 7500 | W8: =INDEX(Product[#All],MATCH(Sales[[#This Row],[Product_ID]],Product[[#All],[Product_ID]],0),MATCH("List_Price",Product[#Headers],0)) -> 10500 | X8: =Sales[[#This Row],[Quantity]]*(Sales[[#This Row],[List_Price]]*(1-Sales[[#This Row],[Discount]])) -> 47250 | Y8: =Sales[[#This Row],[Profit]]/Sales[[#This Row],[Cost_Amount]] -> 0.26
A9: S0008 | B9: 45754 | C9: =MONTH(Sales[[#This Row],[Sale_Date]]) -> 4 | D9: =CHOOSE(C9,"January","February","March","April","May","June","July","August","September","October","November","December") -> April | E9: E010 | F9: C021 | G9: P009 | H9: 9 | I9: 0.05 | J9: 58140 | K9: 40500 | L9: 17640 | M9: East | N9: Completed | O9: สุภัสสรา ศรีทอง | P9: Sales | Q9: บริษัท แกรนด์เอเชีย จำกัด | R9: Retail Chain | S9: Bronze | T9: Network Switch | U9: =INDEX(Product[#All],MATCH(Sales[[#This Row],[Product_ID]],Product[[#All],[Product_ID]],0),MATCH(Sales[[#Headers],[Category]],Product[#Headers],0)) -> IT Equipment | V9: =INDEX(Product[#All],MATCH(Sales[[#This Row],[Product_ID]],Product[[#All],[Product_ID]],0),MATCH(Sales[[#Headers],[Unit_Cost]],Product[#Headers],0)) -> 4500 | W9: =INDEX(Product[#All],MATCH(Sales[[#This Row],[Product_ID]],Product[[#All],[Product_ID]],0),MATCH("List_Price",Product[#Headers],0)) -> 6800 | X9: =Sales[[#This Row],[Quantity]]*(Sales[[#This Row],[List_Price]]*(1-Sales[[#This Row],[Discount]])) -> 58140 | Y9: =Sales[[#This Row],[Profit]]/Sales[[#This Row],[Cost_Amount]] -> 0.43555556
A10: S0009 | B10: 45684 | C10: =MONTH(Sales[[#This Row],[Sale_Date]]) -> 1 | D10: =CHOOSE(C10,"January","February","March","April","May","June","July","August","September","October","November","December") -> January | E10: E047 | F10: C011 | G10: P006 | H10: 13 | I10: 0.08 | J10: 86112 | K10: 62400 | L10: 23712 | M10: South | N10: Completed | O10: พิมพ์ลภัส รุ่งเรือง | P10: IT | Q10: บริษัท ไบรท์โซลูชัน จำกัด | R10: SME | S10: Bronze | T10: Office Chair Ergo | U10: =INDEX(Product[#All],MATCH(Sales[[#This Row],[Product_ID]],Product[[#All],[Product_ID]],0),MATCH(Sales[[#Headers],[Category]],Product[#Headers],0)) -> Office | V10: =INDEX(Product[#All],MATCH(Sales[[#This Row],[Product_ID]],Product[[#All],[Product_ID]],0),MATCH(Sales[[#Headers],[Unit_Cost]],Product[#Headers],0)) -> 4800 | W10: =INDEX(Product[#All],MATCH(Sales[[#This Row],[Product_ID]],Product[[#All],[Product_ID]],0),MATCH("List_Price",Product[#Headers],0)) -> 7200 | X10: =Sales[[#This Row],[Quantity]]*(Sales[[#This Row],[List_Price]]*(1-Sales[[#This Row],[Discount]])) -> 86112 | Y10: =Sales[[#This Row],[Profit]]/Sales[[#This Row],[Cost_Amount]] -> 0.38
A11: S0010 | B11: 45833 | C11: =MONTH(Sales[[#This Row],[Sale_Date]]) -> 6 | D11: =CHOOSE(C11,"January","February","March","April","May","June","July","August","September","October","November","December") -> June | E11: E028 | F11: C031 | G11: P016 | H11: 10 | I11: 0.03 | J11: 40740 | K11: 28000 | L11: 12740 | M11: East | N11: Completed | O11: อธิป สมบูรณ์ | P11: Sales | Q11: บริษัท โปรเกรสซีฟ จำกัด | R11: Retail Chain | S11: Bronze | T11: UPS 1000VA | U11: =INDEX(Product[#All],MATCH(Sales[[#This Row],[Product_ID]],Product[[#All],[Product_ID]],0),MATCH(Sales[[#Headers],[Category]],Product[#Headers],0)) -> IT Equipment | V11: =INDEX(Product[#All],MATCH(Sales[[#This Row],[Product_ID]],Product[[#All],[Product_ID]],0),MATCH(Sales[[#Headers],[Unit_Cost]],Product[#Headers],0)) -> 2800 | W11: =INDEX(Product[#All],MATCH(Sales[[#This Row],[Product_ID]],Product[[#All],[Product_ID]],0),MATCH("List_Price",Product[#Headers],0)) -> 4200 | X11: =Sales[[#This Row],[Quantity]]*(Sales[[#This Row],[List_Price]]*(1-Sales[[#This Row],[Discount]])) -> 40740 | Y11: =Sales[[#This Row],[Profit]]/Sales[[#This Row],[Cost_Amount]] -> 0.455
A12: S0011 | B12: 45824 | C12: =MONTH(Sales[[#This Row],[Sale_Date]]) -> 6 | D12: =CHOOSE(C12,"January","February","March","April","May","June","July","August","September","October","November","December") -> June | E12: E009 | F12: C010 | G12: P008 | H12: 9 | I12: 0.1 | J12: 72900 | K12: 58500 | L12: 14400 | M12: East | N12: Completed | O12: สิริกานต์ มงคลชัย | P12: Sales | Q12: บริษัท โกลบอลคอนเนค จำกัด | R12: SME | S12: Bronze | T12: Printer Laser | U12: =INDEX(Product[#All],MATCH(Sales[[#This Row],[Product_ID]],Product[[#All],[Product_ID]],0),MATCH(Sales[[#Headers],[Category]],Product[#Headers],0)) -> Office | V12: =INDEX(Product[#All],MATCH(Sales[[#This Row],[Product_ID]],Product[[#All],[Product_ID]],0),MATCH(Sales[[#Headers],[Unit_Cost]],Product[#Headers],0)) -> 6500 | W12: =INDEX(Product[#All],MATCH(Sales[[#This Row],[Product_ID]],Product[[#All],[Product_ID]],0),MATCH("List_Price",Product[#Headers],0)) -> 9000 | X12: =Sales[[#This Row],[Quantity]]*(Sales[[#This Row],[List_Price]]*(1-Sales[[#This Row],[Discount]])) -> 72900 | Y12: =Sales[[#This Row],[Profit]]/Sales[[#This Row],[Cost_Amount]] -> 0.24615385
A13: S0012 | B13: 45739 | C13: =MONTH(Sales[[#This Row],[Sale_Date]]) -> 3 | D13: =CHOOSE(C13,"January","February","March","April","May","June","July","August","September","October","November","December") -> March | E13: E001 | F13: C011 | G13: P013 | H13: 13 | I13: 0.1 | J13: 105300 | K13: 84500 | L13: 20800 | M13: South | N13: Completed | O13: นที นาคะ | P13: Sales | Q13: บริษัท ไบรท์โซลูชัน จำกัด | R13: SME | S13: Bronze | T13: Tablet 10 Inch | U13: =INDEX(Product[#All],MATCH(Sales[[#This Row],[Product_ID]],Product[[#All],[Product_ID]],0),MATCH(Sales[[#Headers],[Category]],Product[#Headers],0)) -> IT Equipment | V13: =INDEX(Product[#All],MATCH(Sales[[#This Row],[Product_ID]],Product[[#All],[Product_ID]],0),MATCH(Sales[[#Headers],[Unit_Cost]],Product[#Headers],0)) -> 6500 | W13: =INDEX(Product[#All],MATCH(Sales[[#This Row],[Product_ID]],Product[[#All],[Product_ID]],0),MATCH("List_Price",Product[#Headers],0)) -> 9000 | X13: =Sales[[#This Row],[Quantity]]*(Sales[[#This Row],[List_Price]]*(1-Sales[[#This Row],[Discount]])) -> 105300 | Y13: =Sales[[#This Row],[Profit]]/Sales[[#This Row],[Cost_Amount]] -> 0.24615385
A14: S0013 | B14: 45757 | C14: =MONTH(Sales[[#This Row],[Sale_Date]]) -> 4 | D14: =CHOOSE(C14,"January","February","March","April","May","June","July","August","September","October","November","December") -> April | E14: E032 | F14: C039 | G14: P017 | H14: 14 | I14: 0.05 | J14: 86450 | K14: 58800 | L14: 27650 | M14: Central | N14: Completed | O14: รณกร รุ่งเรือง | P14: Finance | Q14: บริษัท เวลธ์เทรด จำกัด | R14: SME | S14: Silver | T14: Office Desk | U14: =INDEX(Product[#All],MATCH(Sales[[#This Row],[Product_ID]],Product[[#All],[Product_ID]],0),MATCH(Sales[[#Headers],[Category]],Product[#Headers],0)) -> Office | V14: =INDEX(Product[#All],MATCH(Sales[[#This Row],[Product_ID]],Product[[#All],[Product_ID]],0),MATCH(Sales[[#Headers],[Unit_Cost]],Product[#Headers],0)) -> 4200 | W14: =INDEX(Product[#All],MATCH(Sales[[#This Row],[Product_ID]],Product[[#All],[Product_ID]],0),MATCH("List_Price",Product[#Headers],0)) -> 6500 | X14: =Sales[[#This Row],[Quantity]]*(Sales[[#This Row],[List_Price]]*(1-Sales[[#This Row],[Discount]])) -> 86450 | Y14: =Sales[[#This Row],[Profit]]/Sales[[#This Row],[Cost_Amount]] -> 0.4702381
... A18: S0017 | B18: 45742 | C18: =MONTH(Sales[[#This Row],[Sale_Date]]) -> 3 | D18: =CHOOSE(C18,"January","February","March","April","May","June","July","August","September","October","November","December") -> March | E18: E094 | F18: C028 | G18: P002 | H18: 10 | I18: 0.05 | J18: 361000 | K18: 300000 | L18: 61000 | M18: South | N18: Completed | O18: สรวิชญ์ อุดมทรัพย์ | P18: Customer Service | Q18: บริษัท สปีดคอมเมิร์ซ จำกัด | R18: SME | S18: Gold | T18: Laptop Business 15 | U18: =INDEX(Product[#All],MATCH(Sales[[#This Row],[Product_ID]],Product[[#All],[Product_ID]],0),MATCH(Sales[[#Headers],[Category]],Product[#Headers],0)) -> IT Equipment | V18: =INDEX(Product[#All],MATCH(Sales[[#This Row],[Product_ID]],Product[[#All],[Product_ID]],0),MATCH(Sales[[#Headers],[Unit_Cost]],Product[#Headers],0)) -> 30000 | W18: =INDEX(Product[#All],MATCH(Sales[[#This Row],[Product_ID]],Product[[#All],[Product_ID]],0),MATCH("List_Price",Product[#Headers],0)) -> 38000 | X18: =Sales[[#This Row],[Quantity]]*(Sales[[#This Row],[List_Price]]*(1-Sales[[#This Row],[Discount]])) -> 361000 | Y18: =Sales[[#This Row],[Profit]]/Sales[[#This Row],[Cost_Amount]] -> 0.20333333
A19: S0018 | B19: 45707 | C19: =MONTH(Sales[[#This Row],[Sale_Date]]) -> 2 | D19: =CHOOSE(C19,"January","February","March","April","May","June","July","August","September","October","November","December") -> February | E19: E012 | F19: C023 | G19: P008 | H19: =Sales[[#This Row],[Cost_Amount]]/INDEX('02_Products'!A1:E21,MATCH("P008",'02_Products'!A1:A21,0),MATCH("Unit_Cost",'02_Products'!A1:E1,0)) -> 3 | I19: 0.05 | J19: 25650 | K19: 19500 | L19: 6150 | M19: North | N19: Completed | O19: วรเมธ กาญจนวัฒน์ | P19: Sales | Q19: บริษัท โฟกัสซัพพลาย จำกัด | R19: Enterprise | S19: Bronze | T19: Printer Laser | U19: =INDEX(Product[#All],MATCH(Sales[[#This Row],[Product_ID]],Product[[#All],[Product_ID]],0),MATCH(Sales[[#Headers],[Category]],Product[#Headers],0)) -> Office | V19: =INDEX(Product[#All],MATCH(Sales[[#This Row],[Product_ID]],Product[[#All],[Product_ID]],0),MATCH(Sales[[#Headers],[Unit_Cost]],Product[#Headers],0)) -> 6500 | W19: =INDEX(Product[#All],MATCH(Sales[[#This Row],[Product_ID]],Product[[#All],[Product_ID]],0),MATCH("List_Price",Product[#Headers],0)) -> 9000 | X19: =Sales[[#This Row],[Quantity]]*(Sales[[#This Row],[List_Price]]*(1-Sales[[#This Row],[Discount]])) -> 25650 | Y19: =Sales[[#This Row],[Profit]]/Sales[[#This Row],[Cost_Amount]] -> 0.31538462
A20: S0019 | B20: 45709 | C20: =MONTH(Sales[[#This Row],[Sale_Date]]) -> 2 | D20: =CHOOSE(C20,"January","February","March","April","May","June","July","August","September","October","November","December") -> February | E20: E073 | F20: C017 | G20: P001 | H20: 5 | I20: 0 | J20: 260000 | K20: 210000 | L20: 50000 | M20: East | N20: Pending | O20: มนัสวี ธรรมรักษ์ | P20: Operations | Q20: บริษัท เรดโรส จำกัด | R20: Retail Chain | S20: Gold | T20: Laptop Pro 14 | U20: =INDEX(Product[#All],MATCH(Sales[[#This Row],[Product_ID]],Product[[#All],[Product_ID]],0),MATCH(Sales[[#Headers],[Category]],Product[#Headers],0)) -> IT Equipment | V20: =INDEX(Product[#All],MATCH(Sales[[#This Row],[Product_ID]],Product[[#All],[Product_ID]],0),MATCH(Sales[[#Headers],[Unit_Cost]],Product[#Headers],0)) -> 42000 | W20: =INDEX(Product[#All],MATCH(Sales[[#This Row],[Product_ID]],Product[[#All],[Product_ID]],0),MATCH("List_Price",Product[#Headers],0)) -> 52000 | X20: =Sales[[#This Row],[Quantity]]*(Sales[[#This Row],[List_Price]]*(1-Sales[[#This Row],[Discount]])) -> 260000 | Y20: =Sales[[#This Row],[Profit]]/Sales[[#This Row],[Cost_Amount]] -> 0.23809524
A21: S0020 | B21: 45678 | C21: =MONTH(Sales[[#This Row],[Sale_Date]]) -> 1 | D21: =CHOOSE(C21,"January","February","March","April","May","June","July","August","September","October","November","December") -> January | E21: E037 | F21: C015 | G21: P010 | H21: 6 | I21: 0.12 | J21: 17952 | K21: 13200 | L21: 4752 | M21: Northeast | N21: Unknow | O21: นภัสสร จันทร์โอชา | P21: Finance | Q21: บริษัท ไพรม์เวิร์ค จำกัด | R21: SME | S21: Gold | T21: SSD 1TB | U21: =INDEX(Product[#All],MATCH(Sales[[#This Row],[Product_ID]],Product[[#All],[Product_ID]],0),MATCH(Sales[[#Headers],[Category]],Product[#Headers],0)) -> IT Equipment | V21: =INDEX(Product[#All],MATCH(Sales[[#This Row],[Product_ID]],Product[[#All],[Product_ID]],0),MATCH(Sales[[#Headers],[Unit_Cost]],Product[#Headers],0)) -> 2200 | W21: =INDEX(Product[#All],MATCH(Sales[[#This Row],[Product_ID]],Product[[#All],[Product_ID]],0),MATCH("List_Price",Product[#Headers],0)) -> 3400 | X21: =Sales[[#This Row],[Quantity]]*(Sales[[#This Row],[List_Price]]*(1-Sales[[#This Row],[Discount]])) -> 17952 | Y21: =Sales[[#This Row],[Profit]]/Sales[[#This Row],[Cost_Amount]] -> 0.36
A22: S0021 | B22: 45701 | C22: =MONTH(Sales[[#This Row],[Sale_Date]]) -> 2 | D22: =CHOOSE(C22,"January","February","March","April","May","June","July","August","September","October","November","December") -> February | E22: E081 | F22: C042 | G22: P015 | H22: 9 | I22: 0 | J22: 43200 | K22: 28800 | L22: 14400 | M22: Central | N22: Completed | O22: อัญชลี ชาญณรงค์ | P22: Marketing | Q22: บริษัท ครีเอทีฟเวิร์ค จำกัด | R22: SME | S22: Bronze | T22: Router WiFi 6 | U22: =INDEX(Product[#All],MATCH(Sales[[#This Row],[Product_ID]],Product[[#All],[Product_ID]],0),MATCH(Sales[[#Headers],[Category]],Product[#Headers],0)) -> IT Equipment | V22: =INDEX(Product[#All],MATCH(Sales[[#This Row],[Product_ID]],Product[[#All],[Product_ID]],0),MATCH(Sales[[#Headers],[Unit_Cost]],Product[#Headers],0)) -> 3200 | W22: =INDEX(Product[#All],MATCH(Sales[[#This Row],[Product_ID]],Product[[#All],[Product_ID]],0),MATCH("List_Price",Product[#Headers],0)) -> 4800 | X22: =Sales[[#This Row],[Quantity]]*(Sales[[#This Row],[List_Price]]*(1-Sales[[#This Row],[Discount]])) -> 43200 | Y22: =Sales[[#This Row],[Profit]]/Sales[[#This Row],[Cost_Amount]] -> 0.5
A23: S0022 | B23: 45767 | C23: =MONTH(Sales[[#This Row],[Sale_Date]]) -> 4 | D23: =CHOOSE(C23,"January","February","March","April","May","June","July","August","September","October","November","December") -> April | E23: E021 | F23: C003 | G23: P002 | H23: 14 | I23: 0.1 | J23: 478800 | K23: 420000 | L23: 58800 | M23: North | N23: Completed | O23: นราวิชญ์ รุ่งเรือง | P23: Sales | Q23: บริษัท กรีนเวฟ จำกัด | R23: Retail Chain | S23: Gold | T23: Laptop Business 15 | U23: =INDEX(Product[#All],MATCH(Sales[[#This Row],[Product_ID]],Product[[#All],[Product_ID]],0),MATCH(Sales[[#Headers],[Category]],Product[#Headers],0)) -> IT Equipment | V23: =INDEX(Product[#All],MATCH(Sales[[#This Row],[Product_ID]],Product[[#All],[Product_ID]],0),MATCH(Sales[[#Headers],[Unit_Cost]],Product[#Headers],0)) -> 30000 | W23: =INDEX(Product[#All],MATCH(Sales[[#This Row],[Product_ID]],Product[[#All],[Product_ID]],0),MATCH("List_Price",Product[#Headers],0)) -> 38000 | X23: =Sales[[#This Row],[Quantity]]*(Sales[[#This Row],[List_Price]]*(1-Sales[[#This Row],[Discount]])) -> 478800 | Y23: =Sales[[#This Row],[Profit]]/Sales[[#This Row],[Cost_Amount]] -> 0.14
A24: S0023 | B24: 45740 | C24: =MONTH(Sales[[#This Row],[Sale_Date]]) -> 3 | D24: =CHOOSE(C24,"January","February","March","April","May","June","July","August","September","October","November","December") -> March | E24: E044 | F24: C043 | G24: P003 | H24: 12 | I24: 0 | J24: 144000 | K24: 102000 | L24: 42000 | M24: Central | N24: Completed | O24: อธิป สุขเกษม | P24: IT | Q24: บริษัท ดิจิเทค จำกัด | R24: Enterprise | S24: Silver | T24: Monitor 27 Inch | U24: =INDEX(Product[#All],MATCH(Sales[[#This Row],[Product_ID]],Product[[#All],[Product_ID]],0),MATCH(Sales[[#Headers],[Category]],Product[#Headers],0)) -> IT Equipment | V24: =INDEX(Product[#All],MATCH(Sales[[#This Row],[Product_ID]],Product[[#All],[Product_ID]],0),MATCH(Sales[[#Headers],[Unit_Cost]],Product[#Headers],0)) -> 8500 | W24: =INDEX(Product[#All],MATCH(Sales[[#This Row],[Product_ID]],Product[[#All],[Product_ID]],0),MATCH("List_Price",Product[#Headers],0)) -> 12000 | X24: =Sales[[#This Row],[Quantity]]*(Sales[[#This Row],[List_Price]]*(1-Sales[[#This Row],[Discount]])) -> 144000 | Y24: =Sales[[#This Row],[Profit]]/Sales[[#This Row],[Cost_Amount]] -> 0.41176471
A25: S0024 | B25: 45835 | C25: =MONTH(Sales[[#This Row],[Sale_Date]]) -> 6 | D25: =CHOOSE(C25,"January","February","March","April","May","June","July","August","September","October","November","December") -> June | E25: E066 | F25: C019 | G25: P019 | H25: 8 | I25: 0 | J25: 28800 | K25: 19200 | L25: 9600 | M25: Central | N25: Cancelled | O25: นภัสสร รัตนกุล | P25: Operations | Q25: บริษัท เอเวอร์กรีน จำกัด | R25: Enterprise | S25: Bronze | T25: External HDD 2TB | U25: =INDEX(Product[#All],MATCH(Sales[[#This Row],[Product_ID]],Product[[#All],[Product_ID]],0),MATCH(Sales[[#Headers],[Category]],Product[#Headers],0)) -> IT Equipment | V25: =INDEX(Product[#All],MATCH(Sales[[#This Row],[Product_ID]],Product[[#All],[Product_ID]],0),MATCH(Sales[[#Headers],[Unit_Cost]],Product[#Headers],0)) -> 2400 | W25: =INDEX(Product[#All],MATCH(Sales[[#This Row],[Product_ID]],Product[[#All],[Product_ID]],0),MATCH("List_Price",Product[#Headers],0)) -> 3600 | X25: =Sales[[#This Row],[Quantity]]*(Sales[[#This Row],[List_Price]]*(1-Sales[[#This Row],[Discount]])) -> 28800 | Y25: =Sales[[#This Row],[Profit]]/Sales[[#This Row],[Cost_Amount]] -> 0.5
A26: S0025 | B26: 45669 | C26: =MONTH(Sales[[#This Row],[Sale_Date]]) -> 1 | D26: =CHOOSE(C26,"January","February","March","April","May","June","July","August","September","October","November","December") -> January | E26: E074 | F26: C050 | G26: P015 | H26: 6 | I26: 0 | J26: 28800 | K26: 19200 | L26: 9600 | M26: South | N26: Cancelled | O26: พิมพ์ชนก พงษ์พานิช | P26: Operations | Q26: บริษัท พีเอสเอส จำกัด | R26: Retail Chain | S26: Silver | T26: Router WiFi 6 | U26: =INDEX(Product[#All],MATCH(Sales[[#This Row],[Product_ID]],Product[[#All],[Product_ID]],0),MATCH(Sales[[#Headers],[Category]],Product[#Headers],0)) -> IT Equipment | V26: =INDEX(Product[#All],MATCH(Sales[[#This Row],[Product_ID]],Product[[#All],[Product_ID]],0),MATCH(Sales[[#Headers],[Unit_Cost]],Product[#Headers],0)) -> 3200 | W26: =INDEX(Product[#All],MATCH(Sales[[#This Row],[Product_ID]],Product[[#All],[Product_ID]],0),MATCH("List_Price",Product[#Headers],0)) -> 4800 | X26: =Sales[[#This Row],[Quantity]]*(Sales[[#This Row],[List_Price]]*(1-Sales[[#This Row],[Discount]])) -> 28800 | Y26: =Sales[[#This Row],[Profit]]/Sales[[#This Row],[Cost_Amount]] -> 0.5
A27: S0026 | B27: 45692 | C27: =MONTH(Sales[[#This Row],[Sale_Date]]) -> 2 | D27: =CHOOSE(C27,"January","February","March","April","May","June","July","August","September","October","November","December") -> February | E27: E048 | F27: C026 | G27: P016 | H27: 14 | I27: 0.1 | J27: 52920 | K27: 39200 | L27: 13720 | M27: Northeast | N27: Completed | O27: นภัสสร วรเศรษฐ์ | P27: IT | Q27: บริษัท สมาร์ทเวิร์ค จำกัด | R27: SME | S27: Bronze | T27: UPS 1000VA | U27: =INDEX(Product[#All],MATCH(Sales[[#This Row],[Product_ID]],Product[[#All],[Product_ID]],0),MATCH(Sales[[#Headers],[Category]],Product[#Headers],0)) -> IT Equipment | V27: =INDEX(Product[#All],MATCH(Sales[[#This Row],[Product_ID]],Product[[#All],[Product_ID]],0),MATCH(Sales[[#Headers],[Unit_Cost]],Product[#Headers],0)) -> 2800 | W27: =INDEX(Product[#All],MATCH(Sales[[#This Row],[Product_ID]],Product[[#All],[Product_ID]],0),MATCH("List_Price",Product[#Headers],0)) -> 4200 | X27: =Sales[[#This Row],[Quantity]]*(Sales[[#This Row],[List_Price]]*(1-Sales[[#This Row],[Discount]])) -> 52920 | Y27: =Sales[[#This Row],[Profit]]/Sales[[#This Row],[Cost_Amount]] -> 0.35
A28: S0027 | B28: 45716 | C28: =MONTH(Sales[[#This Row],[Sale_Date]]) -> 2 | D28: =CHOOSE(C28,"January","February","March","April","May","June","July","August","September","October","November","December") -> February | E28: E045 | F28: C042 | G28: P008 | H28: 13 | I28: 0 | J28: 117000 | K28: 84500 | L28: 32500 | M28: Central | N28: Completed | O28: ธนกร วรานนท์ | P28: IT | Q28: บริษัท ครีเอทีฟเวิร์ค จำกัด | R28: SME | S28: Bronze | T28: Printer Laser | U28: =INDEX(Product[#All],MATCH(Sales[[#This Row],[Product_ID]],Product[[#All],[Product_ID]],0),MATCH(Sales[[#Headers],[Category]],Product[#Headers],0)) -> Office | V28: =INDEX(Product[#All],MATCH(Sales[[#This Row],[Product_ID]],Product[[#All],[Product_ID]],0),MATCH(Sales[[#Headers],[Unit_Cost]],Product[#Headers],0)) -> 6500 | W28: =INDEX(Product[#All],MATCH(Sales[[#This Row],[Product_ID]],Product[[#All],[Product_ID]],0),MATCH("List_Price",Product[#Headers],0)) -> 9000 | X28: =Sales[[#This Row],[Quantity]]*(Sales[[#This Row],[List_Price]]*(1-Sales[[#This Row],[Discount]])) -> 117000 | Y28: =Sales[[#This Row],[Profit]]/Sales[[#This Row],[Cost_Amount]] -> 0.38461538
A29: S0028 | B29: 45751 | C29: =MONTH(Sales[[#This Row],[Sale_Date]]) -> 4 | D29: =CHOOSE(C29,"January","February","March","April","May","June","July","August","September","October","November","December") -> April | E29: E076 | F29: C012 | G29: P006 | H29: 6 | I29: 0 | J29: 43200 | K29: 28800 | L29: 14400 | M29: South | N29: Completed | O29: ศรัณย์ แสงทอง | P29: Operations | Q29: บริษัท ไทยโปรซิสเต็ม จำกัด | R29: Retail Chain | S29: Bronze | T29: Office Chair Ergo | U29: =INDEX(Product[#All],MATCH(Sales[[#This Row],[Product_ID]],Product[[#All],[Product_ID]],0),MATCH(Sales[[#Headers],[Category]],Product[#Headers],0)) -> Office | V29: =INDEX(Product[#All],MATCH(Sales[[#This Row],[Product_ID]],Product[[#All],[Product_ID]],0),MATCH(Sales[[#Headers],[Unit_Cost]],Product[#Headers],0)) -> 4800 | W29: =INDEX(Product[#All],MATCH(Sales[[#This Row],[Product_ID]],Product[[#All],[Product_ID]],0),MATCH("List_Price",Product[#Headers],0)) -> 7200 | X29: =Sales[[#This Row],[Quantity]]*(Sales[[#This Row],[List_Price]]*(1-Sales[[#This Row],[Discount]])) -> 43200 | Y29: =Sales[[#This Row],[Profit]]/Sales[[#This Row],[Cost_Amount]] -> 0.5
A30: S0029 | B30: 45670 | C30: =MONTH(Sales[[#This Row],[Sale_Date]]) -> 1 | D30: =CHOOSE(C30,"January","February","March","April","May","June","July","August","September","October","November","December") -> January | E30: E059 | F30: C018 | G30: P001 | H30: 2 | I30: 0.08 | J30: 95680 | K30: 84000 | L30: 11680 | M30: Northeast | N30: Completed | O30: ธีรภัทร ศรีทอง | P30: Operations | Q30: บริษัท ซันไรส์ จำกัด | R30: Retail Chain | S30: Bronze | T30: Laptop Pro 14 | U30: =INDEX(Product[#All],MATCH(Sales[[#This Row],[Product_ID]],Product[[#All],[Product_ID]],0),MATCH(Sales[[#Headers],[Category]],Product[#Headers],0)) -> IT Equipment | V30: =INDEX(Product[#All],MATCH(Sales[[#This Row],[Product_ID]],Product[[#All],[Product_ID]],0),MATCH(Sales[[#Headers],[Unit_Cost]],Product[#Headers],0)) -> 42000 | W30: =INDEX(Product[#All],MATCH(Sales[[#This Row],[Product_ID]],Product[[#All],[Product_ID]],0),MATCH("List_Price",Product[#Headers],0)) -> 52000 | X30: =Sales[[#This Row],[Quantity]]*(Sales[[#This Row],[List_Price]]*(1-Sales[[#This Row],[Discount]])) -> 95680 | Y30: =Sales[[#This Row],[Profit]]/Sales[[#This Row],[Cost_Amount]] -> 0.13904762
A31: S0030 | B31: 45798 | C31: =MONTH(Sales[[#This Row],[Sale_Date]]) -> 5 | D31: =CHOOSE(C31,"January","February","March","April","May","June","July","August","September","October","November","December") -> May | E31: E055 | F31: C043 | G31: P015 | H31: 13 | I31: 0 | J31: 62400 | K31: 41600 | L31: 20800 | M31: Central | N31: Completed | O31: รณกร มงคลชัย | P31: HR | Q31: บริษัท ดิจิเทค จำกัด | R31: Enterprise | S31: Silver | T31: Router WiFi 6 | U31: =INDEX(Product[#All],MATCH(Sales[[#This Row],[Product_ID]],Product[[#All],[Product_ID]],0),MATCH(Sales[[#Headers],[Category]],Product[#Headers],0)) -> IT Equipment | V31: =INDEX(Product[#All],MATCH(Sales[[#This Row],[Product_ID]],Product[[#All],[Product_ID]],0),MATCH(Sales[[#Headers],[Unit_Cost]],Product[#Headers],0)) -> 3200 | W31: =INDEX(Product[#All],MATCH(Sales[[#This Row],[Product_ID]],Product[[#All],[Product_ID]],0),MATCH("List_Price",Product[#Headers],0)) -> 4800 | X31: =Sales[[#This Row],[Quantity]]*(Sales[[#This Row],[List_Price]]*(1-Sales[[#This Row],[Discount]])) -> 62400 | Y31: =Sales[[#This Row],[Profit]]/Sales[[#This Row],[Cost_Amount]] -> 0.5
... A62: S0061 | B62: 45692 | C62: =MONTH(Sales[[#This Row],[Sale_Date]]) -> 2 | D62: =CHOOSE(C62,"January","February","March","April","May","June","July","August","September","October","November","December") -> February | E62: E056 | F62: C023 | G62: P018 | H62: 15 | I62: 0.12 | J62: 47520 | K62: 36000 | L62: 11520 | M62: North | N62: Cancelled | O62: ณัฐริกา บุญส่ง | P62: HR | Q62: บริษัท โฟกัสซัพพลาย จำกัด | R62: Enterprise | S62: Bronze | T62: USB-C Dock | U62: =INDEX(Product[#All],MATCH(Sales[[#This Row],[Product_ID]],Product[[#All],[Product_ID]],0),MATCH(Sales[[#Headers],[Category]],Product[#Headers],0)) -> Accessories | V62: =INDEX(Product[#All],MATCH(Sales[[#This Row],[Product_ID]],Product[[#All],[Product_ID]],0),MATCH(Sales[[#Headers],[Unit_Cost]],Product[#Headers],0)) -> 2400 | W62: =INDEX(Product[#All],MATCH(Sales[[#This Row],[Product_ID]],Product[[#All],[Product_ID]],0),MATCH("List_Price",Product[#Headers],0)) -> 3600 | X62: =Sales[[#This Row],[Quantity]]*(Sales[[#This Row],[List_Price]]*(1-Sales[[#This Row],[Discount]])) -> 47520 | Y62: =Sales[[#This Row],[Profit]]/Sales[[#This Row],[Cost_Amount]] -> 0.32
A63: S0062 | B63: 45738 | C63: =MONTH(Sales[[#This Row],[Sale_Date]]) -> 3 | D63: =CHOOSE(C63,"January","February","March","April","May","June","July","August","September","October","November","December") -> March | E63: E045 | F63: C006 | G63: P014 | H63: 18 | I63: =((Sales[[#This Row],[Quantity]]*'02_Products'!E15)-J63)/(Sales[[#This Row],[Quantity]]*Products!F15) -> 0.12 | J63: 253440 | K63: 207000 | L63: 46440 | M63: North | N63: Completed | O63: ธนกร วรานนท์ | P63: IT | Q63: บริษัท เอเชียซัพพลาย จำกัด | R63: Retail Chain | S63: Silver | T63: Projector | U63: =INDEX(Product[#All],MATCH(Sales[[#This Row],[Product_ID]],Product[[#All],[Product_ID]],0),MATCH(Sales[[#Headers],[Category]],Product[#Headers],0)) -> Office | V63: =INDEX(Product[#All],MATCH(Sales[[#This Row],[Product_ID]],Product[[#All],[Product_ID]],0),MATCH(Sales[[#Headers],[Unit_Cost]],Product[#Headers],0)) -> 11500 | W63: =INDEX(Product[#All],MATCH(Sales[[#This Row],[Product_ID]],Product[[#All],[Product_ID]],0),MATCH("List_Price",Product[#Headers],0)) -> 16000 | X63: =Sales[[#This Row],[Quantity]]*(Sales[[#This Row],[List_Price]]*(1-Sales[[#This Row],[Discount]])) -> 253440 | Y63: =Sales[[#This Row],[Profit]]/Sales[[#This Row],[Cost_Amount]] -> 0.22434783
A64: S0063 | B64: 45746 | C64: =MONTH(Sales[[#This Row],[Sale_Date]]) -> 3 | D64: =CHOOSE(C64,"January","February","March","April","May","June","July","August","September","October","November","December") -> March | E64: E087 | F64: C040 | G64: P015 | H64: 10 | I64: 0.1 | J64: 43200 | K64: 32000 | L64: 11200 | M64: Central | N64: Completed | O64: ภานุวัฒน์ ภักดี | P64: Customer Service | Q64: บริษัท ซิกม่า จำกัด | R64: Enterprise | S64: Silver | T64: Router WiFi 6 | U64: =INDEX(Product[#All],MATCH(Sales[[#This Row],[Product_ID]],Product[[#All],[Product_ID]],0),MATCH(Sales[[#Headers],[Category]],Product[#Headers],0)) -> IT Equipment | V64: =INDEX(Product[#All],MATCH(Sales[[#This Row],[Product_ID]],Product[[#All],[Product_ID]],0),MATCH(Sales[[#Headers],[Unit_Cost]],Product[#Headers],0)) -> 3200 | W64: =INDEX(Product[#All],MATCH(Sales[[#This Row],[Product_ID]],Product[[#All],[Product_ID]],0),MATCH("List_Price",Product[#Headers],0)) -> 4800 | X64: =Sales[[#This Row],[Quantity]]*(Sales[[#This Row],[List_Price]]*(1-Sales[[#This Row],[Discount]])) -> 43200 | Y64: =Sales[[#This Row],[Profit]]/Sales[[#This Row],[Cost_Amount]] -> 0.35
A65: S0064 | B65: 45687 | C65: =MONTH(Sales[[#This Row],[Sale_Date]]) -> 1 | D65: =CHOOSE(C65,"January","February","March","April","May","June","July","August","September","October","November","December") -> January | E65: E008 | F65: C016 | G65: P004 | H65: 11 | I65: 0.1 | J65: 27720 | K65: 19800 | L65: 7920 | M65: East | N65: Pending | O65: วรัญญา บุญมี | P65: Sales | Q65: บริษัท บลูโอเชียน จำกัด | R65: SME | S65: Gold | T65: Mechanical Keyboard | U65: =INDEX(Product[#All],MATCH(Sales[[#This Row],[Product_ID]],Product[[#All],[Product_ID]],0),MATCH(Sales[[#Headers],[Category]],Product[#Headers],0)) -> Accessories | V65: =INDEX(Product[#All],MATCH(Sales[[#This Row],[Product_ID]],Product[[#All],[Product_ID]],0),MATCH(Sales[[#Headers],[Unit_Cost]],Product[#Headers],0)) -> 1800 | W65: =INDEX(Product[#All],MATCH(Sales[[#This Row],[Product_ID]],Product[[#All],[Product_ID]],0),MATCH("List_Price",Product[#Headers],0)) -> 2800 | X65: =Sales[[#This Row],[Quantity]]*(Sales[[#This Row],[List_Price]]*(1-Sales[[#This Row],[Discount]])) -> 27720 | Y65: =Sales[[#This Row],[Profit]]/Sales[[#This Row],[Cost_Amount]] -> 0.4
A66: S0065 | B66: 45766 | C66: =MONTH(Sales[[#This Row],[Sale_Date]]) -> 4 | D66: =CHOOSE(C66,"January","February","March","April","May","June","July","August","September","October","November","December") -> April | E66: E015 | F66: C029 | G66: P014 | H66: 18 | I66: 0.03 | J66: 279360 | K66: 207000 | L66: 72360 | M66: South | N66: Completed | O66: ภานุวัฒน์ ศรีทอง | P66: Sales | Q66: บริษัท ทรีสตาร์ จำกัด | R66: Enterprise | S66: Silver | T66: Projector | U66: =INDEX(Product[#All],MATCH(Sales[[#This Row],[Product_ID]],Product[[#All],[Product_ID]],0),MATCH(Sales[[#Headers],[Category]],Product[#Headers],0)) -> Office | V66: =INDEX(Product[#All],MATCH(Sales[[#This Row],[Product_ID]],Product[[#All],[Product_ID]],0),MATCH(Sales[[#Headers],[Unit_Cost]],Product[#Headers],0)) -> 11500 | W66: =INDEX(Product[#All],MATCH(Sales[[#This Row],[Product_ID]],Product[[#All],[Product_ID]],0),MATCH("List_Price",Product[#Headers],0)) -> 16000 | X66: =Sales[[#This Row],[Quantity]]*(Sales[[#This Row],[List_Price]]*(1-Sales[[#This Row],[Discount]])) -> 279360 | Y66: =Sales[[#This Row],[Profit]]/Sales[[#This Row],[Cost_Amount]] -> 0.34956522
A67: S0066 | B67: 45726 | C67: =MONTH(Sales[[#This Row],[Sale_Date]]) -> 3 | D67: =CHOOSE(C67,"January","February","March","April","May","June","July","August","September","October","November","December") -> March | E67: E035 | F67: C006 | G67: P013 | H67: 2 | I67: 0 | J67: 18000 | K67: 13000 | L67: 5000 | M67: North | N67: Completed | O67: อัครพล บุญมี | P67: Finance | Q67: บริษัท เอเชียซัพพลาย จำกัด | R67: Retail Chain | S67: Silver | T67: Tablet 10 Inch | U67: =INDEX(Product[#All],MATCH(Sales[[#This Row],[Product_ID]],Product[[#All],[Product_ID]],0),MATCH(Sales[[#Headers],[Category]],Product[#Headers],0)) -> IT Equipment | V67: =INDEX(Product[#All],MATCH(Sales[[#This Row],[Product_ID]],Product[[#All],[Product_ID]],0),MATCH(Sales[[#Headers],[Unit_Cost]],Product[#Headers],0)) -> 6500 | W67: =INDEX(Product[#All],MATCH(Sales[[#This Row],[Product_ID]],Product[[#All],[Product_ID]],0),MATCH("List_Price",Product[#Headers],0)) -> 9000 | X67: =Sales[[#This Row],[Quantity]]*(Sales[[#This Row],[List_Price]]*(1-Sales[[#This Row],[Discount]])) -> 18000 | Y67: =Sales[[#This Row],[Profit]]/Sales[[#This Row],[Cost_Amount]] -> 0.38461538
A68: S0067 | B68: 45733 | C68: =MONTH(Sales[[#This Row],[Sale_Date]]) -> 3 | D68: =CHOOSE(C68,"January","February","March","April","May","June","July","August","September","October","November","December") -> March | E68: E002 | F68: C037 | G68: P008 | H68: 2 | I68: 0.1 | J68: 16200 | K68: 13000 | L68: 3200 | M68: North | N68: Pending | O68: วรพล ธนากุล | P68: Sales | Q68: บริษัท เอ็นเตอร์ไพรส์ไทย จำกัด | R68: SME | S68: Bronze | T68: Printer Laser | U68: =INDEX(Product[#All],MATCH(Sales[[#This Row],[Product_ID]],Product[[#All],[Product_ID]],0),MATCH(Sales[[#Headers],[Category]],Product[#Headers],0)) -> Office | V68: =INDEX(Product[#All],MATCH(Sales[[#This Row],[Product_ID]],Product[[#All],[Product_ID]],0),MATCH(Sales[[#Headers],[Unit_Cost]],Product[#Headers],0)) -> 6500 | W68: =INDEX(Product[#All],MATCH(Sales[[#This Row],[Product_ID]],Product[[#All],[Product_ID]],0),MATCH("List_Price",Product[#Headers],0)) -> 9000 | X68: =Sales[[#This Row],[Quantity]]*(Sales[[#This Row],[List_Price]]*(1-Sales[[#This Row],[Discount]])) -> 16200 | Y68: =Sales[[#This Row],[Profit]]/Sales[[#This Row],[Cost_Amount]] -> 0.24615385
A69: S0068 | B69: 45715 | C69: =MONTH(Sales[[#This Row],[Sale_Date]]) -> 2 | D69: =CHOOSE(C69,"January","February","March","April","May","June","July","August","September","October","November","December") -> February | E69: E048 | F69: C004 | G69: P017 | H69: 18 | I69: 0.12 | J69: 102960 | K69: 75600 | L69: 27360 | M69: Central | N69: Completed | O69: นภัสสร วรเศรษฐ์ | P69: IT | Q69: บริษัท นอร์ทสตาร์ จำกัด | R69: Retail Chain | S69: Bronze | T69: Office Desk | U69: =INDEX(Product[#All],MATCH(Sales[[#This Row],[Product_ID]],Product[[#All],[Product_ID]],0),MATCH(Sales[[#Headers],[Category]],Product[#Headers],0)) -> Office | V69: =INDEX(Product[#All],MATCH(Sales[[#This Row],[Product_ID]],Product[[#All],[Product_ID]],0),MATCH(Sales[[#Headers],[Unit_Cost]],Product[#Headers],0)) -> 4200 | W69: =INDEX(Product[#All],MATCH(Sales[[#This Row],[Product_ID]],Product[[#All],[Product_ID]],0),MATCH("List_Price",Product[#Headers],0)) -> 6500 | X69: =Sales[[#This Row],[Quantity]]*(Sales[[#This Row],[List_Price]]*(1-Sales[[#This Row],[Discount]])) -> 102960 | Y69: =Sales[[#This Row],[Profit]]/Sales[[#This Row],[Cost_Amount]] -> 0.36190476
A70: S0069 | B70: 45757 | C70: =MONTH(Sales[[#This Row],[Sale_Date]]) -> 4 | D70: =CHOOSE(C70,"January","February","March","April","May","June","July","August","September","October","November","December") -> April | E70: E021 | F70: C030 | G70: P020 | H70: 2 | I70: 0.05 | J70: 9880 | K70: 7000 | L70: 2880 | M70: Central | N70: Cancelled | O70: นราวิชญ์ รุ่งเรือง | P70: Sales | Q70: บริษัท วิชั่นเน็ต จำกัด | R70: Enterprise | S70: Silver | T70: Barcode Scanner | U70: =INDEX(Product[#All],MATCH(Sales[[#This Row],[Product_ID]],Product[[#All],[Product_ID]],0),MATCH(Sales[[#Headers],[Category]],Product[#Headers],0)) -> Operations | V70: =INDEX(Product[#All],MATCH(Sales[[#This Row],[Product_ID]],Product[[#All],[Product_ID]],0),MATCH(Sales[[#Headers],[Unit_Cost]],Product[#Headers],0)) -> 3500 | W70: =INDEX(Product[#All],MATCH(Sales[[#This Row],[Product_ID]],Product[[#All],[Product_ID]],0),MATCH("List_Price",Product[#Headers],0)) -> 5200 | X70: =Sales[[#This Row],[Quantity]]*(Sales[[#This Row],[List_Price]]*(1-Sales[[#This Row],[Discount]])) -> 9880 | Y70: =Sales[[#This Row],[Profit]]/Sales[[#This Row],[Cost_Amount]] -> 0.41142857
A71: S0070 | B71: 45816 | C71: =MONTH(Sales[[#This Row],[Sale_Date]]) -> 6 | D71: =CHOOSE(C71,"January","February","March","April","May","June","July","August","September","October","November","December") -> June | E71: E061 | F71: C038 | G71: P001 | H71: 9 | I71: 0 | J71: 468000 | K71: 378000 | L71: 90000 | M71: Central | N71: Completed | O71: ชญานิศ พิบูลย์ | P71: Operations | Q71: บริษัท โกลด์สโตน จำกัด | R71: Enterprise | S71: Silver | T71: Laptop Pro 14 | U71: =INDEX(Product[#All],MATCH(Sales[[#This Row],[Product_ID]],Product[[#All],[Product_ID]],0),MATCH(Sales[[#Headers],[Category]],Product[#Headers],0)) -> IT Equipment | V71: =INDEX(Product[#All],MATCH(Sales[[#This Row],[Product_ID]],Product[[#All],[Product_ID]],0),MATCH(Sales[[#Headers],[Unit_Cost]],Product[#Headers],0)) -> 42000 | W71: =INDEX(Product[#All],MATCH(Sales[[#This Row],[Product_ID]],Product[[#All],[Product_ID]],0),MATCH("List_Price",Product[#Headers],0)) -> 52000 | X71: =Sales[[#This Row],[Quantity]]*(Sales[[#This Row],[List_Price]]*(1-Sales[[#This Row],[Discount]])) -> 468000 | Y71: =Sales[[#This Row],[Profit]]/Sales[[#This Row],[Cost_Amount]] -> 0.23809524
A72: S0071 | B72: 45808 | C72: =MONTH(Sales[[#This Row],[Sale_Date]]) -> 5 | D72: =CHOOSE(C72,"January","February","March","April","May","June","July","August","September","October","November","December") -> May | E72: E054 | F72: C044 | G72: P018 | H72: 12 | I72: 0.12 | J72: 38016 | K72: 28800 | L72: 9216 | M72: East | N72: Completed | O72: รินรดา ศักดิ์ชัย | P72: HR | Q72: บริษัท ออริจินัลซัพพลาย จำกัด | R72: Retail Chain | S72: Bronze | T72: USB-C Dock | U72: =INDEX(Product[#All],MATCH(Sales[[#This Row],[Product_ID]],Product[[#All],[Product_ID]],0),MATCH(Sales[[#Headers],[Category]],Product[#Headers],0)) -> Accessories | V72: =INDEX(Product[#All],MATCH(Sales[[#This Row],[Product_ID]],Product[[#All],[Product_ID]],0),MATCH(Sales[[#Headers],[Unit_Cost]],Product[#Headers],0)) -> 2400 | W72: =INDEX(Product[#All],MATCH(Sales[[#This Row],[Product_ID]],Product[[#All],[Product_ID]],0),MATCH("List_Price",Product[#Headers],0)) -> 3600 | X72: =Sales[[#This Row],[Quantity]]*(Sales[[#This Row],[List_Price]]*(1-Sales[[#This Row],[Discount]])) -> 38016 | Y72: =Sales[[#This Row],[Profit]]/Sales[[#This Row],[Cost_Amount]] -> 0.32
A73: S0072 | B73: 45677 | C73: =MONTH(Sales[[#This Row],[Sale_Date]]) -> 1 | D73: =CHOOSE(C73,"January","February","March","April","May","June","July","August","September","October","November","December") -> January | E73: E092 | F73: C039 | G73: P015 | H73: 6 | I73: 0.1 | J73: 25920 | K73: 19200 | L73: 6720 | M73: Central | N73: Pending | O73: ณัฐพล พัฒนวงศ์ | P73: Customer Service | Q73: บริษัท เวลธ์เทรด จำกัด | R73: SME | S73: Silver | T73: Router WiFi 6 | U73: =INDEX(Product[#All],MATCH(Sales[[#This Row],[Product_ID]],Product[[#All],[Product_ID]],0),MATCH(Sales[[#Headers],[Category]],Product[#Headers],0)) -> IT Equipment | V73: =INDEX(Product[#All],MATCH(Sales[[#This Row],[Product_ID]],Product[[#All],[Product_ID]],0),MATCH(Sales[[#Headers],[Unit_Cost]],Product[#Headers],0)) -> 3200 | W73: =INDEX(Product[#All],MATCH(Sales[[#This Row],[Product_ID]],Product[[#All],[Product_ID]],0),MATCH("List_Price",Product[#Headers],0)) -> 4800 | X73: =Sales[[#This Row],[Quantity]]*(Sales[[#This Row],[List_Price]]*(1-Sales[[#This Row],[Discount]])) -> 25920 | Y73: =Sales[[#This Row],[Profit]]/Sales[[#This Row],[Cost_Amount]] -> 0.35
...

Sheet Employees
A1: Employee_ID | B1: Employee_Name | C1: Department | D1: Level | E1: Monthly_Salary | F1: Performance_Target | G1: Net_Sales | H1: Profit
A2: E001 | B2: นที นาคะ | C2: Sales | D2: Mid | E2: 51000 | F2: 800000 | G2: =SUMIF(Sales[Employee_Name],Employees[[#This Row],[Employee_Name]],Sales[Net_Sales]) -> 115000 | H2: =SUMIF(Sales[Employee_Name],Employees[[#This Row],[Employee_Name]],Sales[Profit]) -> 24100
A3: E002 | B3: วรพล ธนากุล | C3: Sales | D3: Senior | E3: 39000 | F3: 1130000 | G3: =SUMIF(Sales[Employee_Name],Employees[[#This Row],[Employee_Name]],Sales[Net_Sales]) -> 144450 | H3: =SUMIF(Sales[Employee_Name],Employees[[#This Row],[Employee_Name]],Sales[Profit]) -> 41450
A4: E003 | B4: อัญชลี ทองดี | C4: Sales | D4: Junior | E4: 32000 | F4: 1040000 | G4: =SUMIF(Sales[Employee_Name],Employees[[#This Row],[Employee_Name]],Sales[Net_Sales]) -> 0 | H4: =SUMIF(Sales[Employee_Name],Employees[[#This Row],[Employee_Name]],Sales[Profit]) -> 0
A5: E004 | B5: อัญชลี เจริญกิจ | C5: Sales | D5: Mid | E5: 44500 | F5: 720000 | G5: =SUMIF(Sales[Employee_Name],Employees[[#This Row],[Employee_Name]],Sales[Net_Sales]) -> 12222 | H5: =SUMIF(Sales[Employee_Name],Employees[[#This Row],[Employee_Name]],Sales[Profit]) -> 3822
A6: E005 | B6: ปวีณา วัฒนชัย | C6: Sales | D6: Mid | E6: 31500 | F6: 1060000 | G6: =SUMIF(Sales[Employee_Name],Employees[[#This Row],[Employee_Name]],Sales[Net_Sales]) -> 1255431 | H6: =SUMIF(Sales[Employee_Name],Employees[[#This Row],[Employee_Name]],Sales[Profit]) -> 189631
A7: E006 | B7: สุภัสสรา ศักดิ์ชัย | C7: Sales | D7: Mid | E7: 37500 | F7: 720000 | G7: =SUMIF(Sales[Employee_Name],Employees[[#This Row],[Employee_Name]],Sales[Net_Sales]) -> 25840 | H7: =SUMIF(Sales[Employee_Name],Employees[[#This Row],[Employee_Name]],Sales[Profit]) -> 7840
A8: E007 | B8: ณัฐริกา ภักดี | C8: Sales | D8: Senior | E8: 34000 | F8: 1200000 | G8: =SUMIF(Sales[Employee_Name],Employees[[#This Row],[Employee_Name]],Sales[Net_Sales]) -> 50232 | H8: =SUMIF(Sales[Employee_Name],Employees[[#This Row],[Employee_Name]],Sales[Profit]) -> 16882
A9: E008 | B9: วรัญญา บุญมี | C9: Sales | D9: Junior | E9: 51000 | F9: 1130000 | G9: =SUMIF(Sales[Employee_Name],Employees[[#This Row],[Employee_Name]],Sales[Net_Sales]) -> 27720 | H9: =SUMIF(Sales[Employee_Name],Employees[[#This Row],[Employee_Name]],Sales[Profit]) -> 7920
